..........F
======================================================================
FAIL: test_solve_2 (__main__.TestCollatz)
----------------------------------------------------------------------
Traceback (most recent call last):
  File "TestCollatz.py", line 99, in test_solve_2
    self.assertEqual(w.getvalue(), "0 0 1\n1 1 1\n3 3 8\n5 5 6\n")
AssertionError: '0 0 1\n1 1 1\n0 5 8\n5 5 6\n' != '0 0 1\n1 1 1\n3 3 8\n5 5 6\n'
  0 0 1
  1 1 1
- 0 5 8
+ 3 3 8
  5 5 6


----------------------------------------------------------------------
Ran 13 tests in 0.062s

